<?xml version="1.0" encoding="utf-8"?>
<robot name="X20">


  <link name="base">
    <!-- <inertial>
      <origin
        xyz="0.005 0.000413 0.004"
        rpy="0 0 0" />
      <mass
        value="26.398" />
      <inertia ixx="0.1632" ixy="-5.2136E-05" ixz="-0.00019406" iyy="0.40648" iyz="8.2679E-05" izz="0.52596" />
    </inertial> -->
    <visual>
      <geometry>
        <mesh
          filename="package://X20/meshes/Torso.dae" />
      </geometry>
      <material
        name="">
        <color
          rgba="0.69804 0.69804 0.69804 1" />
      </material>
    </visual>
    <collision>
      <geometry>
        <box size="0.46 0.26 0.15"/>
      </geometry>
    </collision>
  </link>

  <link name="INERTIA">
    <inertial>
      <origin xyz="0.005 0.000413 0.004" />
      <mass value="26.398" />
      <inertia ixx="0.1632" ixy="-5.2136E-05" ixz="-0.00019406" iyy="0.40648" iyz="8.2679E-05" izz="0.52596" />
    </inertial>
  </link>

  <joint name="Base2Inertia" type="fixed">
    <parent link="base" />
    <child link="INERTIA" />
  </joint>


  <link name="LF_HIP">
    <inertial>
      <origin xyz="-0.00075689 -0.0089129 -5.0528E-05" />
      <mass value="1.5767" />
      <inertia ixx="0.0012141" ixy="6.1989E-06" ixz="2.8652E-06" iyy="0.0016912" iyz="3.7E-06" izz="0.0013431" />
    </inertial>
    <visual>
      <geometry>
        <mesh filename="package://X20/meshes/FL_Hip.dae" />
      </geometry>
    </visual>
  </link>

  <joint name="LF_HAA" type="revolute">
    <origin xyz="0.292 0.08 0" />
    <parent link="base" />
    <child link="LF_HIP" />
    <axis xyz="1 0 0" />
    <limit
      lower="-0.38397"
      upper="0.38397"
      effort="126.1"
      velocity="12"  />
  </joint>

  <link name="LF_THIGH">
    <inertial>
      <origin xyz="-0.0025264 -0.022118 -0.0292" />
      <mass value="3.0063" />
      <inertia ixx="0.0058102" ixy="4.2848E-05" ixz="-3.0437E-06" iyy="0.0080686" iyz="-6.889E-05" izz="0.003874" />
    </inertial>
    <visual>
      <geometry>
        <mesh filename="package://X20/meshes/L_Thigh.dae" />
      </geometry>
    </visual>
    <collision>
      <origin xyz="0 0 -0.13" />
      <geometry>
        <cylinder length="0.25" radius="0.04"/>
      </geometry>
    </collision>
  </link>

  <joint name="LF_HFE" type="revolute">
    <origin xyz="0 0.12325 0" />
    <parent link="LF_HIP" />
    <child link="LF_THIGH" />
    <axis xyz="0 -1 0" />
    <limit
      lower="-2.75762"
      upper="0.48869"
      effort="111.4"
      velocity="19"/>
  </joint>

  <link name="LF_SHANK">
    <inertial>
      <origin xyz="0.0075224 2.5888E-05 -0.17586" />
      <mass value="0.54849" />
      <inertia ixx="0.0057" ixy="1.16E-07" ixz="0.000153" iyy="0.006" iyz="-1.12E-06" izz="0.00029" />
    </inertial>
    <visual>
      <geometry>
        <mesh filename="package://X20/meshes/Shank.dae" />
      </geometry>
    </visual>
    <collision>
      <origin xyz="0.00 0 -0.33" />
      <geometry>
        <sphere radius="0.036"/>
      </geometry>
    </collision>
  </link>

  <joint name="LF_KFE" type="revolute">
    <origin xyz="0 0 -0.3" />
    <parent link="LF_THIGH" />
    <child link="LF_SHANK" />
    <axis xyz="0 -1 0" />
    <limit
      lower="0.66322"
      upper="2.84488"
      effort="195.8"
      velocity="19"  />
  </joint>

  <link name="RF_HIP">
    <inertial>
      <origin xyz="-0.000757 0.009 5.0528E-05" />
      <mass value="1.5767" />
      <inertia ixx="0.0012141" ixy="-6.1989E-06" ixz="-2.8652E-06" iyy="0.0016912" iyz="3.7E-06" izz="0.0013431" />
    </inertial>
    <visual>
      <geometry>
        <mesh filename="package://X20/meshes/FR_Hip.dae" />
      </geometry>
    </visual>
  </link>

  <joint name="RF_HAA" type="revolute">
    <origin xyz="0.292 -0.08 0" />
    <parent link="base" />
    <child link="RF_HIP" />
    <axis xyz="-1 0 0" />
    <limit
      lower="-0.38397"
      upper="0.38397"
      effort="126.1"
      velocity="12"  />
  </joint>

  <link name="RF_THIGH">
    <inertial>
      <origin xyz="-0.0025266 0.022119 -0.029194" />
      <mass value="3.0062" />
      <inertia ixx="0.00581" ixy="-4.2781E-05" ixz="-3.0682E-06" iyy="0.0080684" iyz="6.8812E-05" izz="0.0038739" />
    </inertial>
    <visual>
      <geometry>
        <mesh filename="package://X20/meshes/R_Thigh.dae" />
      </geometry>
    </visual>
    <collision>
      <origin xyz="0 0 -0.13" />
      <geometry>
        <cylinder length="0.25" radius="0.04"/>
      </geometry>
    </collision>
  </link>

  <joint name="RF_HFE" type="revolute">
    <origin xyz="0 -0.12325 0" />
    <parent link="RF_HIP" />
    <child link="RF_THIGH" />
    <axis xyz="0 -1 0" />
    <limit
      lower="-2.75762"
      upper="0.48869"
      effort="111.4"
      velocity="19"/>
  </joint>

  <link name="RF_SHANK">
    <inertial>
      <origin xyz="0.0075224 2.5888E-05 -0.17586" />
      <mass value="0.54849" />
      <inertia ixx="0.0057" ixy="1.16E-07" ixz="0.000153" iyy="0.006" iyz="-1.12E-06" izz="0.00029" />
    </inertial>
    <visual>
      <geometry>
        <mesh filename="package://X20/meshes/Shank.dae" />
      </geometry>
    </visual>
    <collision>
      <origin xyz="0.00 0 -0.33" />
      <geometry>
        <sphere radius="0.036"/>
      </geometry>
    </collision>
  </link>

  <joint name="RF_KFE" type="revolute">
    <origin xyz="0 0 -0.3" />
    <parent link="RF_THIGH" />
    <child link="RF_SHANK" />
    <axis xyz="0 -1 0" />
    <limit
      lower="0.66322"
      upper="2.84488"
      effort="195.8"
      velocity="19"  />
  </joint>

  <link name="LH_HIP">
    <inertial>
      <origin xyz="0.000757 -0.009 5.053E-05" />
      <mass value="1.5767" />
      <inertia ixx="0.00121" ixy="-6.2E-06" ixz="2.9E-06" iyy="0.0017" iyz="-3.7E-06" izz="0.00134" />
    </inertial>
    <visual>
      <geometry>
        <mesh filename="package://X20/meshes/HL_Hip.dae" />
      </geometry>
    </visual>
  </link>

  <joint name="LH_HAA" type="revolute">
    <origin xyz="-0.292 0.08 0" />
    <parent link="base" />
    <child link="LH_HIP" />
    <axis xyz="1 0 0" />
    <limit
      lower="-0.38397"
      upper="0.38397"
      effort="126.1"
      velocity="12"  />
  </joint>

  <link name="LH_THIGH">
    <inertial>
      <origin xyz="-0.0025264 -0.022118 -0.0292" />
      <mass value="3.0063" />
      <inertia ixx="0.0058102" ixy="4.2848E-05" ixz="-3.0433E-06" iyy="0.008" iyz="-6.8889E-05" izz="0.003874" />
    </inertial>
    <visual>
      <geometry>
        <mesh filename="package://X20/meshes/L_Thigh.dae" />
      </geometry>
    </visual>
    <collision>
      <origin xyz="0 0 -0.13" />
      <geometry>
        <cylinder length="0.25" radius="0.04"/>
      </geometry>
    </collision>
  </link>

  <joint name="LH_HFE" type="revolute">
    <origin xyz="0 0.12325 0" />
    <parent link="LH_HIP" />
    <child link="LH_THIGH" />
    <axis xyz="0 -1 0" />
    <limit
      lower="-2.75762"
      upper="0.48869"
      effort="111.4"
      velocity="19"/>
  </joint>

  <link name="LH_SHANK">
    <inertial>
      <origin xyz="0.0075224 2.5888E-05 -0.17586" />
      <mass value="0.54849" />
      <inertia ixx="0.0057" ixy="1.16E-07" ixz="0.000153" iyy="0.006" iyz="-1.12E-06" izz="0.00029" />
    </inertial>
    <visual>
      <geometry>
        <mesh filename="package://X20/meshes/Shank.dae" />
      </geometry>
    </visual>
    <collision>
      <origin xyz="0.00 0 -0.33" />
      <geometry>
        <sphere radius="0.036"/>
      </geometry>
    </collision>
  </link>

  <joint name="LH_KFE" type="revolute">
    <origin xyz="0 0 -0.3" />
    <parent link="LH_THIGH" />
    <child link="LH_SHANK" />
    <axis xyz="0 -1 0" />
    <limit
      lower="0.66322"
      upper="2.84488"
      effort="195.8"
      velocity="19"  />
  </joint>

  <link name="RH_HIP">
    <inertial>
      <origin xyz="0.00075689 0.0089129 -5.0528E-05" />
      <mass value="1.5767" />
      <inertia ixx="0.0012141" ixy="6.1989E-06" ixz="-2.8652E-06" iyy="0.0016912" iyz="-3.7E-06" izz="0.0013431" />
    </inertial>
    <visual>
      <geometry>
        <mesh filename="package://X20/meshes/HR_Hip.dae" />
      </geometry>
    </visual>
  </link>

  <joint name="RH_HAA" type="revolute">
    <origin xyz="-0.292 -0.08 0" />
    <parent link="base" />
    <child link="RH_HIP" />
    <axis xyz="-1 0 0" />
    <limit
      lower="-0.38397"
      upper="0.38397"
      effort="126.1"
      velocity="12"  />
  </joint>

  <link name="RH_THIGH">
    <inertial>
      <origin xyz="-0.0025266 0.022119 -0.029194" />
      <mass value="3.0062" />
      <inertia ixx="0.00581" ixy="-4.2781E-05" ixz="-3.0681E-06" iyy="0.0080684" iyz="6.8812E-05" izz="0.0038739" />
    </inertial>
    <visual>
      <geometry>
        <mesh filename="package://X20/meshes/R_Thigh.dae" />
      </geometry>
    </visual>
    <collision>
      <origin xyz="0 0 -0.13" />
      <geometry>
        <cylinder length="0.25" radius="0.04"/>
      </geometry>
    </collision>
  </link>

  <joint name="RH_HFE" type="revolute">
    <origin xyz="0 -0.12325 0" />
    <parent link="RH_HIP" />
    <child link="RH_THIGH" />
    <axis xyz="0 -1 0" />
    <limit
      lower="-2.75762"
      upper="0.48869"
      effort="111.4"
      velocity="19"/>
  </joint>

  <link name="RH_SHANK">
    <inertial>
      <origin xyz="0.0075224 2.589E-05 -0.17586" />
      <mass value="0.54849" />
      <inertia ixx="0.0056981" ixy="1.1608E-07" ixz="0.00015292" iyy="0.0059026" iyz="-1.1243E-06" izz="0.00028822" />
    </inertial>
    <visual>
      <geometry>
        <mesh filename="package://X20/meshes/Shank.dae" />
      </geometry>
    </visual>
    <collision>
      <origin xyz="0.00 0 -0.33" />
      <geometry>
        <sphere radius="0.036"/>
      </geometry>
    </collision>
  </link>

  <joint name="RH_KFE" type="revolute">
    <origin xyz="0 0 -0.3" />
    <parent link="RH_THIGH" />
    <child link="RH_SHANK" />
    <axis xyz="0 -1 0" />
    <limit
      lower="0.66322"
      upper="2.84488"
      effort="195.8"
      velocity="19"  />
  </joint>

  <link name="LF_FOOT">
  </link>
  <joint name = "LF_FOOT_joint" type = "fixed">
    <origin xyz="0 0 -0.33" rpy = "0 0 0"/>
    <parent link="LF_SHANK"/>
    <child link = "LF_FOOT"/>
  </joint>

  <link name="RF_FOOT">
  </link>
  <joint name = "RF_FOOT_joint" type = "fixed">
    <origin xyz="0 0 -0.33" rpy = "0 0 0"/>
    <parent link="RF_SHANK"/>
    <child link = "RF_FOOT"/>
  </joint>


  <link name="LH_FOOT">
  </link>
  <joint name = "LH_FOOT_joint" type = "fixed">
    <origin xyz="0 0 -0.33" rpy = "0 0 0"/>
    <parent link="LH_SHANK"/>
    <child link = "LH_FOOT"/>
  </joint>

  <link name="RH_FOOT">
  </link>
  <joint name = "RH_FOOT_joint" type = "fixed">
    <origin xyz="0 0 -0.33" rpy = "0 0 0"/>
    <parent link="RH_SHANK"/>
    <child link = "RH_FOOT"/>
  </joint>

</robot>

   <!-- ;; Leg Joint Positions: [LF, LH, RF, RH] ;;
   (12,0)  -0.2   ; LF_HAA
   (13,0)  -0.8 ; LF_HFE
   (14,0)  1.7   ; LF_KFE
   (15,0)  -0.2   ; LH_HAA
   (16,0) -0.8   ; LH_HFE
   (17,0)  1.7   ; LH_KFE
   (18,0)  -0.2   ; RF_HAA
   (19,0)  -0.8   ; RF_HFE
   (20,0)  1.7  ; RF_KFE
   (21,0)  -0.2   ; RH_HAA
   (22,0) -0.8   ; RH_HFE
   (23,0)  1.7   ; RH_KFE 
   jointNominalConfig << 0, 0, 0.4, 1.0, 0.0, 0.0, 0.0, -0., -0.87, 1.8, -0., -0.87, 1.8, -0., -0.87, 1.8, -0., -0.87, 1.8;
   kp = 300; kd = 10
   -->